File: upload/sample_data.csv
Time (min),Temperature (C),Storage Modulus (MPa),Loss Modulus (MPa),Stress (MPa),Tan Delta,Frequency (Hz),Drive Force (N),Amplitude (µm),Strain (%),Displacement (µm),Static Force (N),Position (mm),Length (mm),Force (N),Stiffness (N/m),GCA Pressure (kPa gauge),,,,
10.12683,-10.05449,1847.494,62.79527,1.179827,0.03398942,1,2.854673,25.00259,0.06386094,13221.77,2.19E-07,13.22177,0,3.144779,125778.1,1.5169,,,,
12.30583,-10.06601,1857.321,58.812,1.185918,0.03166496,1.6,2.868992,24.9987,0.063851,13221.92,2.7E-06,13.22192,0,3.161013,126447.1,1.6548,,,,
12.9265,-10.07098,1867.623,55.68493,1.19258,0.02981594,2.5,2.882544,25.00047,0.06385552,13221.96,2.19E-06,13.22196,0,3.17877,127148.4,1.58585,,,,
14.3055,-10.06211,1882.063,52.34714,1.201788,0.0278137,5,2.898536,25.00022,0.06385488,13222.05,1.53E-06,13.22205,0,3.203316,128131.5,1.72375,,,,
16.4845,-10.05184,1891.989,50.55606,1.208093,0.02672112,7.9,2.9024,24.9995,0.06385305,13222.22,2.19E-07,13.22222,0,3.22012,128807.4,1.72375,,,,
17.38016,-10.03422,1901.181,49.76394,1.213974,0.02617529,12.6,2.89149,24.99974,0.06385367,13222.28,3.28E-06,13.22228,0,3.235795,129433.1,1.72375,,,,
18.25083,-10.04032,1908.951,49.32092,1.218955,0.02583666,19,2.852599,25.00015,0.0638547,13222.33,2.63E-06,13.22234,0,3.249072,129962.1,1.58585,,,,
18.9215,-10.01146,1918.059,52.50719,1.224703,0.02737516,31.6,2.709806,24.99876,0.06385115,13222.36,2.41E-06,13.22236,0,3.264392,130582.2,1.58585,,,,
19.79216,-10.00353,1922.619,51.98872,1.227719,0.02704056,50,2.354284,25.00088,0.06385657,13222.39,2.19E-06,13.22239,0,3.272432,130892.7,1.58585,,,,
20.18766,-10.00444,1925.233,49.19896,1.229418,0.0255548,79.5,1.453388,25.00148,0.06385812,13222.42,2.04E-06,13.22241,0,3.27696,131070.6,1.58585,,,,
32.25184,-5.086306,1770.852,68.65194,1.13083,0.03876773,1,2.747436,25.00141,0.06385792,13222.88,1.97E-06,13.22288,0,3.014178,120560.3,1.31005,,,,
34.43083,-5.088334,1781.063,63.73451,1.13736,0.03578453,1.6,2.7624,25.00164,0.06385851,13223.03,8.02E-07,13.22303,0,3.031586,121255.5,1.58585,,,,
35.0515,-5.091977,1791.963,59.56944,1.14428,0.03324257,2.5,2.776618,25.00075,0.06385623,13223.09,2.19E-07,13.22309,0,3.050029,121997.5,1.58585,,,,
36.4305,-5.101648,1806.687,54.94014,1.153662,0.03040934,5,2.793052,25.00031,0.06385512,13223.22,2.63E-06,13.22323,0,3.075037,122999.9,1.72375,,,,
38.6095,-5.12504,1816.061,52.76461,1.159703,0.02905442,7.9,2.796339,25.0015,0.06385815,13223.45,9.48E-07,13.22345,0,3.091139,123638.2,1.9306,,,,
39.60867,-5.101337,1825,51.42447,1.165345,0.02817779,12.6,2.784991,25.00008,0.0638545,13223.57,2.19E-06,13.22357,0,3.106177,124246.7,1.86165,,,,
40.583,-5.058828,1832.714,50.84814,1.170238,0.02774472,19,2.746011,24.99937,0.06385272,13223.67,2.63E-06,13.22367,0,3.119218,124771.9,1.7927,,,,
41.35717,-5.028446,1842,53.59293,1.176051,0.02909497,31.6,2.603435,24.9969,0.0638464,13223.73,2.19E-06,13.22373,0,3.134713,125404.1,1.6548,,,,
42.33166,-4.997697,1847.009,52.81031,1.17938,0.02859234,50,2.248774,24.99967,0.06385348,13223.76,1.75E-06,13.22377,0,3.143586,125745.1,1.5169,,,,
42.81766,-4.98971,1849.99,50.25208,1.181298,0.02716343,79.5,1.348642,25,0.06385432,13223.8,1.46E-06,13.2238,0,3.1487,125948,1.58585,,,,
54.32033,-0.1217382,1675.446,77.34851,1.069842,0.04616592,1,2.612449,24.99994,0.06385418,13225.08,1.75E-06,13.22508,0,2.851619,114065,1.03425,,,,
56.49934,-0.1212403,1690.784,70.4104,1.079582,0.04164362,1.6,2.634912,24.99868,0.06385094,13225.1,1.75E-06,13.2251,0,2.877579,115109.3,1.44795,,,,
57.12,-0.121871,1703.897,64.8707,1.088034,0.03807197,2.5,2.65239,25.00052,0.06385566,13225.14,1.31E-06,13.22514,0,2.90011,116001.9,1.5169,,,,
58.499,-0.1087638,1721.194,58.61824,1.09904,0.03405671,5,2.67251,24.99961,0.06385334,13225.26,4.38E-07,13.22526,0,2.929444,117179.6,1.72375,,,,
60.678,-0.1649506,1732.25,55.48186,1.106161,0.03202879,7.9,2.678208,25.00101,0.06385691,13225.5,2.04E-06,13.22551,0,2.948425,117932.2,2.2064,,,,
61.65883,-0.1479999,1742.201,53.65014,1.112485,0.03079445,12.6,2.668413,25.00032,0.06385512,13225.64,8.75E-07,13.22564,0,2.96528,118609.7,2.0685,,,,
62.63316,-0.1015038,1750.513,52.67662,1.117778,0.0300921,19,2.630359,24.99998,0.0638543,13225.78,3.28E-06,13.22578,0,2.979388,119175.6,1.9306,,,,
63.4075,-0.07007157,1760.31,54.7061,1.123978,0.03107753,31.6,2.488753,24.99875,0.06385113,13225.86,2.55E-06,13.22586,0,2.995915,119842.6,1.72375,,,,
64.382,-6.82E-03,1766.034,54.24309,1.127745,0.03071463,50,2.135168,25.00124,0.0638575,13225.94,1.97E-06,13.22594,0,3.005956,120232.3,1.58585,,,,
64.868,0.01177054,1770.434,51.33331,1.130472,0.02899475,79.5,1.237206,24.9994,0.06385279,13225.96,1.75E-06,13.22596,0,3.013224,120531.8,1.58585,,,,
77.037,4.905624,1584.899,86.6178,1.012092,0.05465192,1,2.48386,25.00161,0.06385844,13227.46,2.19E-07,13.22746,0,2.697688,107900.6,1.17215,,,,
79.216,4.937122,1600.804,78.43222,1.022253,0.04899552,1.6,2.507206,25.00172,0.06385871,13227.55,3.14E-06,13.22755,0,2.72477,108983.3,1.44795,,,,
79.83668,4.92825,1615.775,71.28491,1.031786,0.04411809,2.5,2.527193,25.00105,0.063857,13227.58,2.85E-06,13.22758,0,2.750181,110002.6,1.44795,,,,
81.21568,4.905059,1635.118,63.10033,1.044102,0.0385907,5,2.55031,25.00019,0.0638548,13227.68,1.97E-06,13.22768,0,2.783008,111319.5,1.58585,,,,
83.39468,4.916359,1646.827,58.89582,1.051603,0.03576321,7.9,2.556805,25.00077,0.0638563,13227.86,8.02E-07,13.22786,0,2.803002,112116.6,1.6548,,,,
84.39384,4.931782,1657.56,56.17751,1.05846,0.0338917,12.6,2.548294,25.00085,0.0638565,13227.92,1.46E-07,13.22792,0,2.821279,112847.3,1.58585,,,,
85.36816,4.939183,1666.496,54.5426,1.064131,0.03272892,19,2.511118,25.00004,0.06385442,13227.99,3.06E-06,13.22799,0,2.836396,113455.6,1.58585,,,,
86.14234,4.949608,1677.25,56.28138,1.070955,0.03355575,31.6,2.371048,24.99903,0.06385186,13228.03,2.85E-06,13.22803,0,2.854585,114187.8,1.58585,,,,
87.11668,4.949158,1684.146,55.19501,1.07539,0.03277328,50,2.019101,24.99976,0.0638537,13228.07,2.41E-06,13.22807,0,2.866406,114657.3,1.5169,,,,
87.6225,4.965773,1689.02,52.1845,1.078495,0.03089631,79.5,1.122312,24.99959,0.06385328,13228.1,2.19E-06,13.2281,0,2.874682,114989.2,1.5169,,,,
99.837,9.891178,1485.878,96.81356,0.9488081,0.06515576,1,2.341692,25.00028,0.06385503,13229.87,2.19E-06,13.22987,0,2.529007,101159.2,1.1032,,,,
102.016,9.935004,1505.371,87.29366,0.9612897,0.05798816,1.6,2.370471,25.00118,0.06385735,13229.94,1.46E-06,13.22994,0,2.562276,102486.2,1.31005,,,,
102.6367,9.940388,1523.278,78.92141,0.9726837,0.05181026,2.5,2.39464,25.00012,0.06385464,13229.96,1.31E-06,13.22996,0,2.592646,103705.3,1.379,,,,
104.0157,9.910946,1546.004,68.52582,0.9872038,0.0443245,5,2.422808,25.00035,0.06385522,13230.02,8.75E-07,13.23002,0,2.63135,105252.5,1.5169,,,,
106.1947,9.918594,1559.579,62.9003,0.9958749,0.04033158,7.9,2.431848,25.0004,0.06385536,13230.14,2.19E-06,13.23014,0,2.654462,106176.8,1.5169,,,,
107.194,9.928937,1571.446,58.98278,1.003456,0.03753409,12.6,2.424969,25.0005,0.06385561,13230.19,3.06E-06,13.23019,0,2.674669,106984.6,1.44795,,,,
108.1684,9.944321,1581.188,56.59319,1.009703,0.03579156,19,2.389142,25.00114,0.06385724,13230.24,2.63E-06,13.23024,0,2.69132,107647.9,1.44795,,,,
108.9427,9.944098,1592.897,57.70124,1.01712,0.0362241,31.6,2.250524,24.99966,0.06385344,13230.27,2.41E-06,13.23027,0,2.711089,108445,1.5169,,,,
109.917,9.979474,1600.237,56.19605,1.021817,0.03511734,50,1.899284,24.99991,0.0638541,13230.3,2.19E-06,13.2303,0,2.723608,108944.7,1.5169,,,,
110.423,9.956711,1605.87,52.68554,1.025361,0.03280809,79.5,1.003955,24.99862,0.0638508,13230.32,2.04E-06,13.23032,0,2.733056,109328.3,1.44795,,,,
122.8287,14.87465,1382.797,106.539,0.8830176,0.077046,1,2.192592,25.0012,0.06385738,13232.48,2.19E-06,13.23248,0,2.353646,94141.32,1.17215,,,,
125.0077,14.92687,1406.925,96.75882,0.8984228,0.06877326,1.6,2.22834,25.00112,0.06385719,13232.5,1.97E-06,13.2325,0,2.394707,95783.99,1.2411,,,,
125.6282,14.93832,1428.43,87.37991,0.9121468,0.06117199,2.5,2.25782,25.00088,0.0638566,13232.51,1.97E-06,13.23251,0,2.431288,97248.09,1.2411,,,,
127.0072,14.93432,1457.208,74.55179,0.9305139,0.05116074,5,2.292935,25.00065,0.06385598,13232.54,1.75E-06,13.23254,0,2.480245,99207.24,1.44795,,,,
129.1862,14.92293,1471.936,67.85778,0.9399275,0.04610103,7.9,2.305414,25.00087,0.06385654,13232.61,1.24E-06,13.23261,0,2.505337,100210,1.44795,,,,
130.1855,14.9304,1485.597,62.67696,0.9486084,0.04218974,12.6,2.301062,24.99975,0.06385369,13232.64,8.75E-07,13.23264,0,2.528475,101140,1.44795,,,,
131.1598,14.93326,1496.604,59.07847,0.9556375,0.03947502,19,2.267004,24.99977,0.06385374,13232.66,6.57E-07,13.23266,0,2.547211,101889.4,1.44795,,,,
131.934,14.95471,1508.933,58.91846,0.9634457,0.03904645,31.6,2.129322,24.99811,0.0638495,13232.67,6.57E-07,13.23267,0,2.568024,102728.7,1.379,,,,
132.9283,14.94511,1517.239,56.78352,0.9688371,0.03742557,50,1.779824,25.00038,0.0638553,13232.72,3.65E-07,13.23272,0,2.582394,103294.2,1.31005,,,,
133.4342,14.96345,1523.198,52.76142,0.972564,0.0346386,79.5,0.8853966,24.99837,0.06385016,13232.73,2.92E-07,13.23273,0,2.592328,103699.9,1.31005,,,,
145.7953,19.86165,1278.763,115.1094,0.8165806,0.09001625,1,2.040626,25.00108,0.0638571,13234.98,3.28E-06,13.23498,0,2.176561,87058.66,0.89635,,,,
147.9744,19.89448,1307.098,105.6673,0.834649,0.08084122,1.6,2.082752,25.00032,0.06385516,13234.94,0,13.23495,0,2.224721,88987.69,1.2411,,,,
148.595,19.89672,1332.176,96.34664,0.8506861,0.07232272,2.5,2.117793,25.001,0.06385687,13234.94,0,13.23494,0,2.267468,90695.09,1.2411,,,,
149.974,19.9272,1365.899,82.46337,0.8722389,0.06037295,5,2.160188,25.00153,0.06385822,13234.92,2.19E-07,13.23492,0,2.324915,92990.93,1.2411,,,,
152.153,19.9414,1383.455,74.6563,0.8833619,0.05396367,7.9,2.176693,24.99904,0.0638519,13234.94,2.19E-07,13.23494,0,2.354564,94186.13,1.2411,,,,
153.1523,19.94216,1399.43,67.75447,0.8935694,0.04841574,12.6,2.175804,24.99924,0.06385237,13234.94,2.19E-07,13.23494,0,2.381771,95273.76,1.31005,,,,
154.1266,19.93478,1411.968,63.06703,0.9015844,0.04466604,19,2.14399,24.99949,0.06385302,13234.94,1.46E-07,13.23494,0,2.403134,96127.34,1.2411,,,,
154.901,19.95401,1425.529,61.79405,0.910228,0.04334816,31.6,2.008306,24.99908,0.06385196,13234.94,7.3E-08,13.23495,0,2.426174,97050.54,1.31005,,,,
155.8953,19.953,1435.437,58.14482,0.9166086,0.04050671,50,1.661185,25.00055,0.06385572,13234.99,3.28E-06,13.23499,0,2.443181,97725.11,1.2411,,,,
156.4015,19.97332,1441.938,53.23708,0.920687,0.0369205,79.5,0.768172,24.99856,0.06385066,13234.97,1.09E-06,13.23497,0,2.454052,98167.71,1.2411,,,,
168.9787,24.87931,1175.615,120.5578,0.7506886,0.1025486,1,1.888202,25.00025,0.06385496,13237.55,2.19E-07,13.23755,0,2.000928,80036.34,0.8274,,,,
171.1576,24.89696,1207.886,112.2696,0.7713008,0.09294716,1.6,1.935401,25.00042,0.06385541,13237.49,8.75E-07,13.23749,0,2.055869,82233.37,1.1032,,,,
171.7784,24.90457,1236.215,103.6342,0.7893879,0.08383186,2.5,1.97542,25.00034,0.06385521,13237.48,8.75E-07,13.23748,0,2.10408,84162.01,1.2411,,,,
173.1574,24.93127,1274.255,89.8865,0.8136948,0.07054044,5,2.025704,25.00086,0.06385651,13237.43,1.31E-06,13.23743,0,2.168868,86751.75,1.2411,,,,
175.3363,24.94004,1294.752,81.3607,0.826775,0.06283886,7.9,2.046894,25.00061,0.06385588,13237.4,1.39E-06,13.2374,0,2.203733,88147.18,1.1032,,,,
176.3355,24.95748,1313.421,73.49318,0.8386818,0.05595551,12.6,2.049943,25.00016,0.06385474,13237.39,1.53E-06,13.23739,0,2.23547,89418.22,1.17215,,,,
177.31,24.98072,1327.881,67.49416,0.8478797,0.05082846,19,2.020839,24.99912,0.06385208,13237.4,1.53E-06,13.2374,0,2.259987,90402.66,1.17215,,,,
178.0844,24.9587,1343.17,65.17202,0.8575824,0.04852106,31.6,1.887687,24.99739,0.06384766,13237.39,1.53E-06,13.23739,0,2.28585,91443.51,1.2411,,,,
179.1653,24.94361,1354.201,59.52162,0.8647128,0.04395332,50,1.542359,24.99992,0.0638541,13237.42,1.31E-06,13.23742,0,2.304855,92194.51,1.17215,,,,
179.6718,24.9652,1361.908,53.70508,0.8696191,0.03943372,79.5,0.652118,24.99948,0.06385301,13237.44,1.17E-06,13.23744,0,2.317932,92719.19,1.17215,,,,
191.3953,29.90525,1068.485,123.7899,0.682309,0.1158555,1,1.728254,25.00129,0.06385762,13240.36,2.41E-06,13.24036,0,1.818666,72742.88,0.75845,,,,
193.5744,29.88133,1103.124,116.965,0.704356,0.1060306,1.6,1.779303,24.9987,0.063851,13240.35,2.41E-06,13.24035,0,1.87743,75101.14,1.03425,,,,
194.195,29.89563,1134.031,109.6883,0.724151,0.09672422,2.5,1.823786,25.0008,0.06385636,13240.32,2.63E-06,13.24032,0,1.930194,77205.28,1.1032,,,,
195.574,29.91947,1176.869,96.93081,0.7515164,0.08236332,5,1.881634,25.00117,0.06385731,13240.25,3.28E-06,13.24025,0,2.003135,80121.66,1.1032,,,,
197.9216,29.96284,1200.504,88.43634,0.7665681,0.073666,7.9,1.90758,24.99982,0.06385386,13240.16,4.38E-07,13.24016,0,2.043255,81730.78,1.03425,,,,
199.0275,29.98408,1222.247,79.8598,0.780447,0.0653385,12.6,1.915371,24.99967,0.06385348,13240.15,6.57E-07,13.24015,0,2.080248,83211.04,0.9653,,,,
200.1087,30.00715,1239.012,73.07637,0.7912641,0.05897956,19,1.890056,25.0032,0.0638625,13240.14,6.57E-07,13.24014,0,2.109081,84352.41,0.8274,,,,
200.9897,30.00441,1256.819,68.50412,0.8028001,0.05450597,31.6,1.761133,25.00832,0.06387558,13240.17,2.92E-07,13.24017,0,2.13983,85564.69,0.8274,,,,
202.0706,29.9941,1269.251,62.42315,0.810439,0.04918111,50,1.417297,24.999,0.06385178,13240.22,3.28E-06,13.24022,0,2.16019,86411.06,0.75845,,,,
202.5776,30.00296,1278.191,55.25576,0.8160992,0.04322967,79.5,0.5304907,24.99753,0.063848,13240.28,3.06E-06,13.24028,0,2.175278,87019.71,0.75845,,,,
214.237,34.91577,962.3031,123.7136,0.6145325,0.12856,1,1.567706,25.00246,0.0638606,13243.18,8.75E-07,13.24318,0,1.63801,65513.96,0.6895,,,,
216.416,34.88618,997.4506,118.9403,0.636958,0.1192443,1.6,1.620275,25.00167,0.0638586,13243.25,2.19E-07,13.24325,0,1.697784,67906.82,0.89635,,,,
217.0365,34.90439,1029.763,113.3086,0.6575644,0.1100338,2.5,1.667256,25.00063,0.06385593,13243.24,4.38E-07,13.24324,0,1.75271,70106.63,0.9653,,,,
218.4155,34.91637,1075.704,102.5418,0.6869254,0.09532522,5,1.730487,25.00152,0.06385821,13243.19,8.75E-07,13.24319,0,1.83097,73234.36,0.9653,,,,
220.9333,34.98454,1101.972,94.66866,0.7036911,0.08590844,7.9,1.759688,25.00123,0.06385746,13243.16,1.02E-06,13.24316,0,1.875658,75022.65,0.8274,,,,
222.0394,34.99744,1125.732,86.44574,0.7188466,0.07679066,12.6,1.771725,25.00062,0.0638559,13243.17,8.75E-07,13.24316,0,1.916055,76640.29,0.75845,,,,
223.1203,35.01092,1144.89,79.5356,0.7310169,0.0694701,19,1.749798,24.99848,0.06385044,13243.17,8.75E-07,13.24317,0,1.948494,77944.51,0.6895,,,,
224.0012,35.00559,1165.951,74.13594,0.7445345,0.0635841,31.6,1.625797,25.00082,0.06385642,13243.18,8.75E-07,13.24318,0,1.984525,79378.39,0.6895,,,,
225.0822,35.00442,1179.813,66.69753,0.7533829,0.0565323,50,1.284936,25.00072,0.06385615,13243.18,8.75E-07,13.24318,0,2.00811,80322.1,0.62055,,,,
225.5902,35.01938,1190.638,58.25138,0.760177,0.0489245,79.5,0.4042094,24.99682,0.0638462,13243.38,2.85E-06,13.24338,0,2.026219,81059.1,0.62055,,,,
237.2953,39.94252,855.0888,120.6238,0.546013,0.1410659,1,1.403136,25.00008,0.06385454,13246.35,0,13.24635,0,1.455374,58214.78,0.62055,,,,
239.4744,39.91188,889.5754,117.989,0.5680625,0.1326352,1.6,1.455586,25.00133,0.06385772,13246.49,2.63E-06,13.24649,0,1.514146,60562.63,0.8274,,,,
240.0948,39.91025,922.2413,114.2143,0.5889139,0.1238442,2.5,1.503885,25.00098,0.06385681,13246.5,2.41E-06,13.2465,0,1.569725,62786.54,0.8274,,,,
241.4738,39.9565,969.7059,105.9582,0.6192029,0.1092684,5,1.570218,25.00016,0.06385472,13246.51,2.41E-06,13.24651,0,1.650459,66017.94,0.75845,,,,
243.9917,39.99942,997.2494,99.26757,0.636862,0.09954136,7.9,1.601984,25.00295,0.06386186,13246.52,2.19E-06,13.24652,0,1.697528,67893.12,0.6895,,,,
245.0978,40.00604,1023.735,91.85999,0.6537294,0.08973022,12.6,1.617401,25.00116,0.06385728,13246.52,2.19E-06,13.24652,0,1.742488,69696.28,0.62055,,,,
246.1788,40.02387,1044.114,85.35506,0.6667376,0.08174878,19,1.59866,25.00096,0.06385678,13246.51,2.41E-06,13.24651,0,1.777161,71083.69,0.5516,,,,
247.0598,40.01279,1068.705,79.62445,0.682367,0.07450553,31.6,1.479096,24.99826,0.06384988,13246.51,2.41E-06,13.24651,0,1.81882,72757.86,0.48265,,,,
248.1408,39.99676,1083.994,72.11504,0.6921932,0.06652716,50,1.1421,25.00058,0.06385582,13246.52,2.33E-06,13.24652,0,1.845011,73798.72,0.48265,,,,
248.651,40.00678,1096.544,62.56202,0.700122,0.0570538,79.5,0.2724324,24.99754,0.06384802,13246.84,3.06E-06,13.24684,0,1.866145,74653.16,0.48265,,,,
260.412,45.00518,746.2238,114.298,0.4765179,0.1531685,1,1.233803,25.00114,0.06385724,13249.77,8.76E-07,13.24977,0,1.270138,50803.2,0.48265,,,,
262.9284,44.92336,777.7408,113.2944,0.496725,0.1456711,1.6,1.282549,25.00522,0.06386766,13249.92,3.06E-06,13.24992,0,1.323999,52948.89,0.62055,,,,
263.5675,44.925,809.3782,111.4197,0.516867,0.1376609,2.5,1.329977,25.00213,0.06385976,13249.92,3.06E-06,13.24992,0,1.377686,55102.78,0.5516,,,,
264.9465,44.97333,856.3454,105.8808,0.5468184,0.1236426,5,1.396602,25.00022,0.0638549,13249.91,3.06E-06,13.24991,0,1.457521,58300.32,0.5516,,,,
267.4644,44.99803,883.9758,100.8051,0.5645444,0.114036,7.9,1.429142,25.00388,0.06386424,13249.86,0,13.24986,0,1.504769,60181.41,0.48265,,,,
268.5704,45.0124,911.6295,94.78265,0.5821543,0.1039706,12.6,1.446861,25.0017,0.06385865,13249.85,0,13.24985,0,1.551707,62064.09,0.4137,,,,
269.6514,45.0051,934.0563,89.01001,0.5964149,0.09529406,19,1.430734,24.99914,0.06385212,13249.81,5.11E-07,13.24981,0,1.589718,63590.91,0.4137,,,,
270.5322,45.00424,960.2715,84.22191,0.6131721,0.08770637,31.6,1.315224,24.99989,0.06385405,13249.78,6.57E-07,13.24978,0,1.634384,65375.65,0.4137,,,,
271.6135,45.00436,977.9,76.45282,0.6244512,0.07818061,50,0.9825294,25.0008,0.06385636,13249.74,1.02E-06,13.24974,0,1.664448,66575.8,0.4137,,,,
272.126,45.01586,991.7694,66.84906,0.6333085,0.06740384,79.5,0.1478474,25.00082,0.06385644,13250.19,1.09E-06,13.25019,0,1.688056,67520.04,0.4137,,,,
283.887,49.95971,645.5355,105.3266,0.4122092,0.1631616,1,1.074695,25.00042,0.0638554,13252.77,1.31E-06,13.25277,0,1.098726,43948.3,0.2758,,,,
286.4033,49.98906,673.3238,105.858,0.430116,0.1572172,1.6,1.118587,25.00986,0.06387951,13253.1,2.41E-06,13.2531,0,1.146456,45840.14,0.34475,,,,
287.0776,49.99519,702.7816,105.6565,0.4487816,0.1503405,2.5,1.163236,25.0014,0.0638579,13253.16,1.75E-06,13.25316,0,1.196208,47845.64,0.2758,,,,
288.6438,49.9867,747.9255,102.8955,0.4776119,0.1375745,5,1.22835,25.00153,0.06385822,13253.28,8.76E-07,13.25328,0,1.273054,50919.05,0.34475,,,,
290.8228,49.99084,777.1856,99.57447,0.4962537,0.1281219,7.9,1.263806,24.99935,0.06385266,13253.36,0,13.25336,0,1.322743,52911.1,0.34475,,,,
291.929,49.98344,806.016,95.27168,0.5146564,0.1182007,12.6,1.2841,24.99904,0.0638519,13253.39,2.19E-06,13.25339,0,1.371794,54873.88,0.34475,,,,
293.01,49.98422,829.8703,90.73345,0.5299351,0.1093345,19,1.270941,25.00128,0.0638576,13253.36,0,13.25336,0,1.41252,56497.89,0.34475,,,,
293.891,49.99096,857.8316,87.14126,0.5478006,0.1015832,31.6,1.158862,25.00174,0.06385876,13253.34,2.19E-07,13.25334,0,1.460139,58401.5,0.34475,,,,
294.9726,49.99979,877.5129,79.84538,0.560312,0.09099054,50,0.830485,24.9992,0.06385229,13253.33,2.19E-07,13.25333,0,1.493487,59741.41,0.2758,,,,
295.4788,50.01638,896.4364,70.2357,0.5728024,0.0783499,79.5,0.1357529,25.01699,0.06389773,13253.32,2.19E-07,13.25332,0,1.52678,61029.74,0.2758,,,,
307.1204,54.95396,564.4734,96.19191,0.3604479,0.17041,1,0.9449726,25.0005,0.06385561,13256.46,3.28E-06,13.25647,0,0.9607584,38429.56,0.06895,,,,
309.6367,54.97861,591.2626,97.81986,0.3776455,0.1654424,1.6,0.9876655,25.00654,0.06387102,13256.73,1.39E-06,13.25673,0,1.006598,40253.38,0.1379,,,,
310.311,54.98713,618.8232,98.83332,0.3951597,0.1597117,2.5,1.030151,25.0009,0.06385663,13256.8,6.57E-07,13.2568,0,1.053281,42129.72,0.20685,,,,
311.69,54.99482,661.9858,98.33401,0.4227257,0.148544,5,1.093209,25.00113,0.06385722,13256.91,3.28E-06,13.25691,0,1.126757,45068.24,0.20685,,,,
313.869,54.99124,689.7032,96.59439,0.4404539,0.1400521,7.9,1.127114,25.00276,0.06386137,13257.01,2.41E-06,13.25701,0,1.174011,46955.26,0.2758,,,,
314.975,54.99928,717.7504,93.74953,0.4583284,0.1306158,12.6,1.146731,25.00075,0.06385625,13257.04,2.19E-06,13.25704,0,1.221655,48864.72,0.20685,,,,
316.056,54.99672,741.6322,90.65944,0.4735263,0.1222431,19,1.133956,24.998,0.06384921,13257.04,2.19E-06,13.25704,0,1.262164,50490.6,0.2758,,,,
316.937,54.99575,770.306,88.4737,0.4919302,0.1148553,31.6,1.024045,25.00288,0.06386166,13257.04,2.19E-06,13.25704,0,1.311219,52442.72,0.2758,,,,
318.0187,54.99522,791.9093,82.18032,0.505464,0.1037749,50,0.6995288,24.9899,0.06382852,13257.06,2.12E-06,13.25706,0,1.347293,53913.49,0.2758,,,,
318.6032,54.99468,812.547,72.93762,0.5187992,0.08976418,79.5,0.2263738,24.99772,0.0638485,13257.06,1.97E-06,13.25706,0,1.382837,55318.51,0.2758,,,,
331.387,59.99232,492.0561,87.02461,0.3142056,0.1768591,1,0.8278751,25.00052,0.06385564,13260.32,4.38E-07,13.26032,0,0.8375015,33499.37,0.06895,,,,
333.9033,60.00301,517.4229,89.10009,0.3304253,0.1721997,1.6,0.8685078,25.00215,0.06385982,13260.45,3.06E-06,13.26046,0,0.8807345,35226.35,0.06895,,,,
334.524,60.00758,542.9136,90.88231,0.3466894,0.1673974,2.5,0.9084289,25.00113,0.06385722,13260.47,2.92E-06,13.26047,0,0.9240859,36961.76,0.06895,,,,
335.903,60.00176,583.7674,92.20843,0.3728122,0.1579541,5,0.9688691,25.00346,0.06386316,13260.51,2.41E-06,13.26052,0,0.9937149,39743.1,0.06895,,,,
338.0818,59.99361,611.3671,91.90401,0.3903536,0.1503254,7.9,1.002957,24.99803,0.06384928,13260.54,2.19E-06,13.26054,0,1.040471,41622.1,0.06895,,,,
339.188,59.97387,638.9116,90.55132,0.4079454,0.1417275,12.6,1.022532,24.99833,0.06385006,13260.56,2.19E-06,13.26056,0,1.087361,43497.34,0.06895,,,,
340.269,59.97885,662.5339,88.66892,0.4230168,0.133833,19,1.010008,24.99766,0.06384834,13260.58,1.97E-06,13.26058,0,1.127533,45105.56,0.1379,,,,
341.15,59.98709,691.1738,87.73785,0.4413022,0.1269404,31.6,0.9007499,24.99761,0.06384824,13260.56,2.19E-06,13.26056,0,1.176272,47055.38,0.06895,,,,
342.232,59.99386,713.3362,82.48441,0.4554722,0.1156319,50,0.579842,24.9987,0.063851,13260.56,2.19E-06,13.26056,0,1.214042,48564.2,0.1379,,,,
342.8153,59.99624,734.9325,74.47266,0.4692632,0.1013327,79.5,0.3348628,24.99878,0.0638512,13260.6,1.75E-06,13.2606,0,1.250801,50034.48,0.1379,,,,
355.687,64.996,428.705,78.32663,0.2737637,0.1827052,1,0.7245395,25.00155,0.06385828,13264.25,6.57E-07,13.26425,0,0.7297053,29186.4,0.06895,,,,
358.0347,64.99765,451.5067,80.52003,0.2883159,0.1783363,1.6,0.7612595,25.00081,0.06385639,13264.39,3.06E-06,13.26439,0,0.7684936,30738.75,0.06895,,,,
358.6553,65.00102,474.4262,82.62718,0.3029497,0.1741623,2.5,0.7974811,25.00066,0.06385601,13264.41,2.85E-06,13.26441,0,0.8074994,32299.12,0.06895,,,,
360.0344,65.00251,511.6602,85.0193,0.3267035,0.1661636,5,0.8527462,24.99896,0.06385166,13264.44,2.63E-06,13.26444,0,0.8708141,34834.02,0.06895,,,,
362.2134,64.99978,537.2258,85.725,0.3430148,0.1595698,7.9,0.8843575,24.99803,0.06384928,13264.46,2.41E-06,13.26446,0,0.9142913,36574.54,0.06895,,,,
363.3194,65.00126,563.3324,85.66879,0.3596721,0.1520751,12.6,0.9022504,24.99722,0.06384724,13264.46,2.48E-06,13.26446,0,0.9586906,38351.88,0.06895,,,,
364.4004,65.00698,586.2532,84.86925,0.3743187,0.1447655,19,0.8892482,24.99804,0.06384932,13264.43,2.63E-06,13.26443,0,0.9977304,39912.34,0.06895,,,,
365.2815,64.99988,614.572,85.52038,0.3923197,0.1391544,31.6,0.7804328,24.99293,0.06383627,13264.41,2.85E-06,13.26441,0,1.045711,41840.3,0.06895,,,,
366.3641,65.00194,636.933,81.4289,0.4067203,0.1278453,50,0.4633335,25.00068,0.06385606,13264.41,2.85E-06,13.26441,0,1.084096,43362.64,0.06895,,,,
366.913,65.00092,659.3649,74.5244,0.4210457,0.1130245,79.5,0.4480437,25.00076,0.06385626,13264.49,2.19E-06,13.26449,0,1.122279,44889.81,0.06895,,,,
380.0037,69.99966,372.4238,70.40766,0.2378166,0.1890526,1,0.6320518,25.00083,0.06385645,13268.66,5.84E-07,13.26866,0,0.6338899,25354.75,0.06895,,,,
382.3513,69.9977,393.2322,72.48068,0.2510889,0.1843203,1.6,0.6657032,24.99932,0.06385258,13268.78,3.06E-06,13.26878,0,0.6692666,26771.4,0.06895,,,,
382.972,69.99686,413.8104,74.54474,0.2642263,0.1801423,2.5,0.6983809,24.9991,0.06385204,13268.8,2.85E-06,13.2688,0,0.7042838,28172.36,0.06895,,,,
384.351,70.00428,447.3284,77.4273,0.2856382,0.1730883,5,0.7482971,24.99998,0.06385428,13268.83,2.63E-06,13.26883,0,0.7613564,30454.29,0.06895,,,,
386.53,69.9977,470.741,78.79166,0.300559,0.167378,7.9,0.7768835,24.99756,0.06384809,13268.84,2.63E-06,13.26884,0,0.8011274,32048.22,0.06895,,,,
387.6362,69.99732,494.8443,79.60688,0.31595,0.1608726,12.6,0.7921411,24.99767,0.06384838,13268.84,2.63E-06,13.26884,0,0.8421512,33689.19,0.06895,,,,
388.7172,69.99778,516.299,79.86152,0.3296188,0.1546808,19,0.7772928,24.99542,0.06384262,13268.83,2.63E-06,13.26883,0,0.8785848,35149.84,0.06895,,,,
389.5985,70.00385,543.1434,81.85124,0.3467008,0.1506991,31.6,0.6673628,24.99138,0.06383229,13268.81,2.85E-06,13.26881,0,0.9241161,36977.4,0.06895,,,,
390.682,70.00168,564.8247,78.7925,0.3605803,0.139499,50,0.3540178,24.99413,0.06383934,13268.8,2.85E-06,13.2688,0,0.9611113,38453.48,0.06895,,,,
391.2628,69.99718,587.3,72.68218,0.3750144,0.1237564,79.5,0.5580041,24.99986,0.06385398,13268.8,2.85E-06,13.2688,0,0.9995849,39983.61,0.06895,,,,
404.587,74.99392,322.5323,63.07795,0.2060023,0.1955709,1,0.5496518,25.00625,0.06387029,13273.29,1.97E-06,13.27329,0,0.5490903,21958.12,0.06895,,,,
406.9347,74.99475,341.3198,65.09226,0.217929,0.1907075,1.6,0.5800332,24.99788,0.06384892,13273.42,9.49E-07,13.27342,0,0.5808804,23237.18,0.06895,,,,
407.5553,75.00051,359.7864,66.92425,0.2297346,0.1860111,2.5,0.609464,24.99951,0.06385307,13273.43,8.76E-07,13.27343,0,0.6123478,24494.4,0.06895,,,,
408.9344,74.99682,389.8059,69.756,0.248872,0.1789506,5,0.6539426,24.99639,0.06384511,13273.46,6.57E-07,13.27346,0,0.6633575,26538.14,0.06895,,,,
411.1133,74.99665,410.835,71.4222,0.2622967,0.1738464,7.9,0.6790932,24.99626,0.06384479,13273.47,5.84E-07,13.27347,0,0.6991406,27969.8,0.06895,,,,
412.2194,74.9974,432.7067,72.78749,0.2762789,0.1682144,12.6,0.6912328,24.99791,0.063849,13273.46,6.57E-07,13.27346,0,0.7364094,29458.84,0.06895,,,,
413.3008,74.99356,452.4472,73.61852,0.288899,0.1627119,19,0.6742008,24.9993,0.06385255,13273.45,6.57E-07,13.27345,0,0.7700479,30802.78,0.06895,,,,
414.1826,74.99537,477.329,76.3789,0.3048108,0.1600131,31.6,0.5623292,25.00127,0.06385756,13273.44,6.57E-07,13.27345,0,0.8124599,32496.75,0.06895,,,,
415.2674,75.00164,497.6898,74.50625,0.3177903,0.1497042,50,0.2547773,24.99952,0.0638531,13273.48,4.38E-07,13.27348,0,0.8470564,33882.91,0.06895,,,,
415.8277,74.9947,519.3869,69.38916,0.3316511,0.1335982,79.5,0.6634288,25.00002,0.06385437,13273.49,4.38E-07,13.2735,0,0.8840019,35360.06,0.06895,,,,
429.387,79.99106,277.5609,56.3247,0.1772152,0.2029274,1,0.474675,24.99725,0.0638473,13278.56,1.97E-06,13.27856,0,0.4723594,18896.45,0.06895,,,,
431.7347,79.9981,294.598,58.23516,0.188097,0.1976767,1.6,0.5025074,24.9978,0.0638487,13278.66,1.24E-06,13.27867,0,0.5013645,20056.35,0.06895,,,,
432.3554,79.99844,311.211,59.90802,0.1986999,0.1924998,2.5,0.5289832,24.99727,0.06384735,13278.68,1.09E-06,13.27868,0,0.5296261,21187.36,0.06895,,,,
433.7344,79.9975,337.975,62.40262,0.2158143,0.1846368,5,0.5684986,25.00031,0.06385512,13278.71,6.57E-07,13.27871,0,0.5752437,23009.47,0.06895,,,,
436.2524,79.999,356.7447,64.12021,0.2277601,0.179737,7.9,0.5901218,24.99596,0.06384402,13278.71,6.57E-07,13.27871,0,0.6070849,24287.32,0.06895,,,,
437.3587,79.99824,376.2916,65.63778,0.2402606,0.1744333,12.6,0.5987961,24.99815,0.0638496,13278.71,6.57E-07,13.27871,0,0.6404043,25618.08,0.06895,,,,
438.4403,79.99298,393.9634,66.80724,0.2515646,0.1695773,19,0.5788174,25.0002,0.06385482,13278.7,1.09E-06,13.2787,0,0.6705348,26821.18,0.06895,,,,
439.3225,80.00269,416.6255,70.10124,0.266145,0.1682596,31.6,0.464609,25.0105,0.06388113,13278.68,1.09E-06,13.27868,0,0.7093982,28364.02,0.06895,,,,
440.4083,79.9998,435.379,68.97441,0.2779776,0.1584238,50,0.1699088,24.99724,0.06384728,13278.7,6.57E-07,13.2787,0,0.7409372,29640.76,0.06895,,,,
440.9365,79.99824,455.6269,64.67268,0.2909431,0.1419422,79.5,0.7636272,25.00048,0.06385556,13278.72,6.57E-07,13.27872,0,0.7754962,31019.25,0.06895,,,,
452.8787,84.99454,237.0763,49.81956,0.1513858,0.2101414,1,0.4069678,25.00038,0.0638553,13284.14,2.92E-06,13.28414,0,0.4035122,16140.24,0.06895,,,,
455.0576,84.99412,252.3084,51.76036,0.1610958,0.2051472,1.6,0.4319344,24.99782,0.06384877,13284.28,1.82E-06,13.28428,0,0.429394,17177.25,0.06895,,,,
455.6783,84.99432,267.1756,53.33086,0.170608,0.1996097,2.5,0.4557238,25.00072,0.06385615,13284.3,1.53E-06,13.2843,0,0.4547485,18189.42,0.06895,,,,
457.0574,84.99842,291.0621,55.57269,0.1858704,0.1909306,5,0.4906547,25.00196,0.06385934,13284.35,1.31E-06,13.28435,0,0.4954294,19815.62,0.06895,,,,
459.5754,85.00242,307.7655,57.06155,0.1964835,0.1854059,7.9,0.5089864,24.99516,0.06384197,13284.34,1.31E-06,13.28434,0,0.5237183,20952.79,0.06895,,,,
460.682,85.00022,325.1201,58.5065,0.2075639,0.1799535,12.6,0.5142356,24.99527,0.06384224,13284.33,1.46E-06,13.28433,0,0.5532528,22134.3,0.06895,,,,
461.7638,84.99838,340.9964,59.77251,0.2177036,0.1752878,19,0.4915935,24.9957,0.06384336,13284.31,1.53E-06,13.28431,0,0.5802796,23215.17,0.06895,,,,
462.6467,85.00032,361.2536,63.5727,0.2307818,0.1759781,31.6,0.3748224,25.01146,0.0638836,13284.28,1.75E-06,13.28428,0,0.6151389,24594.28,0.06895,,,,
463.7702,84.99996,378.1518,62.66292,0.241565,0.1657084,50,0.1154157,25.01023,0.06388044,13284.26,1.97E-06,13.28426,0,0.6438813,25744.72,0.06895,,,,
464.2978,85.00265,396.577,58.9732,0.253231,0.1487055,79.5,0.8573706,24.99994,0.06385418,13284.28,1.75E-06,13.28428,0,0.6749762,26999.11,0.06895,,,,
478.1787,89.98397,201.1684,43.47911,0.1284636,0.2161329,1,0.3464456,25.00173,0.06385874,13290.72,2.85E-06,13.29073,0,0.3424142,13695.62,0.06895,,,,
480.5263,90.00181,214.7056,45.55958,0.1370783,0.2121956,1.6,0.3687561,24.99626,0.06384478,13290.88,1.68E-06,13.29088,0,0.3653762,14617.24,0.06895,,,,
481.147,90.00281,227.9894,47.23337,0.1455767,0.2071735,2.5,0.3900894,24.99924,0.06385239,13290.9,1.53E-06,13.2909,0,0.3880284,15521.61,0.06895,,,,
482.526,89.99879,249.3972,49.33413,0.1592475,0.1978135,5,0.4210773,24.99946,0.06385296,13290.93,1.31E-06,13.29093,0,0.4244674,16979.06,0.06895,,,,
485.0441,89.99478,264.3723,50.59812,0.168769,0.1913896,7.9,0.4366868,24.99347,0.06383764,13290.9,1.53E-06,13.2909,0,0.4498466,17998.57,0.06895,,,,
486.1508,89.99426,279.7052,51.84328,0.1785815,0.1853497,12.6,0.4388081,24.99687,0.06384632,13290.88,1.53E-06,13.29088,0,0.4760014,19042.44,0.06895,,,,
487.2328,90.00324,293.5456,52.98709,0.1874768,0.1805072,19,0.413171,25.0047,0.06386632,13290.86,1.75E-06,13.29086,0,0.4997114,19984.7,0.06895,,,,
488.1162,90.0035,311.6336,57.11424,0.1988254,0.1832737,31.6,0.2937844,24.97913,0.06380102,13290.84,1.97E-06,13.29084,0,0.5299606,21216.13,0.06895,,,,
489.1802,89.9962,326.4649,56.06693,0.2083722,0.1717396,50,0.1186515,24.98924,0.06382685,13290.82,1.97E-06,13.29082,0,0.5554072,22225.85,0.06895,,,,
489.7056,89.99426,342.8456,52.60324,0.2189338,0.1534313,79.5,0.9435139,25.00138,0.06385784,13290.86,1.75E-06,13.29086,0,0.5835586,23341.06,0.06895,,,,
503.7787,94.99121,168.9091,37.19723,0.1078651,0.2202204,1,0.2916558,25.00218,0.06385989,13298.13,2.19E-06,13.29813,0,0.28751,11499.4,0.06895,,,,
506.1264,94.99413,180.711,39.51032,0.1153772,0.2186381,1.6,0.3113084,24.99683,0.06384623,13298.3,1.97E-06,13.2983,0,0.3075329,12302.88,0.06895,,,,
506.747,94.99134,192.4213,41.34754,0.1228568,0.2148802,2.5,0.3301733,24.99744,0.06384778,13298.32,1.75E-06,13.29832,0,0.3274694,13100.12,0.06895,,,,
508.126,95.00266,211.4458,43.40824,0.1350194,0.2052925,5,0.3574267,25.0004,0.06385534,13298.37,1.31E-06,13.29837,0,0.3598884,14395.31,0.06895,,,,
510.4737,94.99882,224.7228,44.5673,0.143458,0.1983212,7.9,0.370342,24.99352,0.06383778,13298.37,1.31E-06,13.29837,0,0.3823812,15299.22,0.06895,,,,
511.5806,95.00288,238.2713,45.56859,0.1521297,0.1912467,12.6,0.3696106,24.99724,0.0638473,13298.34,1.68E-06,13.29834,0,0.4054952,16221.6,0.06895,,,,
512.6631,94.98453,250.531,46.537,0.1598951,0.1857535,19,0.3413003,24.98753,0.06382248,13298.32,1.75E-06,13.29832,0,0.4261934,17056.25,0.06895,,,,
513.5474,95.00981,266.56,50.301,0.169887,0.1887042,31.6,0.2203076,24.95254,0.0637331,13298.29,1.97E-06,13.29829,0,0.4528266,18147.51,0.06895,,,,
514.6544,95.00888,279.2142,49.2627,0.1783076,0.1764333,50,0.1655655,25.00241,0.06386048,13298.28,2.12E-06,13.29828,0,0.4752712,19009.01,0.06895,,,,
515.1606,95.005,293.71,46.00878,0.1875491,0.156647,79.5,1.022878,25.00034,0.06385521,13298.3,1.97E-06,13.2983,0,0.4999039,19995.88,0.06895,,,,
527.062,99.98957,140.0737,31.07354,0.08944441,0.221837,1,0.2423115,25.00036,0.06385524,13306.75,8.76E-07,13.30675,0,0.2384102,9536.272,0.06895,,,,
529.4097,100.0032,149.9519,33.58228,0.09574097,0.2239537,1.6,0.2589886,24.99745,0.0638478,13306.95,2.85E-06,13.30695,0,0.2551934,10208.78,0.06895,,,,
530.0303,99.99274,160.0378,35.572,0.1021944,0.2222725,2.5,0.275351,25.0008,0.06385637,13306.98,2.63E-06,13.30698,0,0.2723947,10895.44,0.06895,,,,
531.4094,99.99301,176.7522,37.83481,0.11284,0.2140556,5,0.2988982,24.99469,0.06384075,13307.03,2.19E-06,13.30703,0,0.30077,12033.36,0.06895,,,,
533.9278,100.0022,188.4258,38.9072,0.1202992,0.2064856,7.9,0.3093684,24.99608,0.0638443,13307,2.41E-06,13.30701,0,0.3206522,12828.1,0.06895,,,,
535.0356,100.0002,200.3776,39.76422,0.1279256,0.1984464,12.6,0.3060417,24.99528,0.06384228,13307,2.41E-06,13.30701,0,0.3409802,13641.78,0.06895,,,,
536.1186,100.0035,211.0615,40.41938,0.1347887,0.1915052,19,0.275509,25.00312,0.0638623,13306.96,2.63E-06,13.30696,0,0.3592736,14369.15,0.06895,,,,
537.0041,99.99984,224.7898,43.93453,0.1436251,0.1954472,31.6,0.1541327,25.01517,0.06389307,13306.94,2.85E-06,13.30694,0,0.3828266,15303.78,0.06895,,,,
538.2805,99.99796,236.0044,42.97088,0.1506762,0.1820766,50,0.2247112,24.99621,0.06384465,13306.9,3.28E-06,13.3069,0,0.4016209,16067.27,0.06895,,,,
538.7865,99.99592,248.5013,39.69795,0.1586878,0.1597495,79.5,1.096592,25.00142,0.06385794,13306.95,2.85E-06,13.30695,0,0.4229754,16918.06,0.06895,,,,
550.7037,104.9775,114.3471,25.37403,0.07302192,0.2219036,1,0.1981011,25.00218,0.0638599,13317.04,2.85E-06,13.31704,0,0.1946368,7784.792,0.06895,,,,
553.0512,105.0016,122.5642,27.9374,0.0782482,0.2279411,1.6,0.2121006,24.99543,0.06384265,13317.2,1.53E-06,13.3172,0,0.2085672,8344.214,0.06895,,,,
553.6717,105.0004,131.0701,30.01491,0.08368631,0.228999,2.5,0.2259479,24.99773,0.06384854,13317.24,1.09E-06,13.31724,0,0.2230623,8923.301,0.06895,,,,
555.0507,104.9975,145.5272,32.40617,0.09290078,0.2226811,5,0.2459685,24.99337,0.0638374,13317.25,1.09E-06,13.31726,0,0.247623,9907.549,0.06895,,,,
557.5693,104.9982,155.7782,33.55785,0.09944356,0.2154208,7.9,0.2541949,24.99308,0.06383664,13317.27,1.09E-06,13.31727,0,0.2650625,10605.44,0.06895,,,,
558.6772,104.9961,166.2562,34.34694,0.1061434,0.2065904,12.6,0.2485904,24.99567,0.06384326,13317.29,8.76E-07,13.31729,0,0.2829206,11318.78,0.06895,,,,
559.7608,105.0022,175.5385,35.12553,0.111987,0.2001016,19,0.2158827,24.97726,0.06379624,13317.26,1.09E-06,13.31726,0,0.2984964,11950.73,0.06895,,,,
560.6482,105.0003,187.5675,38.03749,0.1195625,0.2027936,31.6,0.09789844,24.9567,0.06374374,13317.24,1.24E-06,13.31724,0,0.3186888,12769.66,0.06895,,,,
561.8344,104.9936,197.0483,36.93678,0.1258757,0.1874504,50,0.2835723,25.0103,0.06388064,13317.2,1.46E-06,13.3172,0,0.3355163,13415.12,0.06895,,,,
562.3388,105.0004,207.7198,33.55142,0.1326369,0.1615225,79.5,1.163424,24.99978,0.06385375,13317.25,1.09E-06,13.31725,0,0.353538,14141.64,0.06895,,,,
574.2703,109.9963,91.49891,20.36613,0.05843076,0.2225833,1,0.1587353,25.00204,0.06385952,13329.85,2.04E-06,13.32985,0,0.1557447,6229.28,0.06895,,,,
576.618,110.0016,98.17337,22.68233,0.06266541,0.2310436,1.6,0.17013,24.99102,0.06383139,13330.1,7.3E-08,13.33011,0,0.167032,6683.68,0.06895,,,,
577.2385,109.9973,105.1488,24.7082,0.06714024,0.2349832,2.5,0.1815312,24.99932,0.0638526,13330.15,3.14E-06,13.33015,0,0.1789594,7158.571,0.06895,,,,
578.6175,109.9989,117.2586,27.26765,0.07485498,0.232543,5,0.1978494,24.99343,0.06383754,13330.18,2.85E-06,13.33018,0,0.1995227,7983.007,0.06895,,,,
581.1363,110.0069,126.1802,28.3777,0.08054912,0.2248983,7.9,0.2039502,24.99306,0.06383658,13330.11,2.19E-06,13.33011,0,0.2147002,8590.394,0.06895,,,,
582.2451,110.0064,135.2453,29.19218,0.086344,0.2158462,12.6,0.1961645,24.99539,0.06384254,13330.05,2.19E-07,13.33005,0,0.2301463,9207.55,0.06895,,,,
583.3299,109.999,143.3035,29.64512,0.09151547,0.2068695,19,0.1619162,25.00274,0.06386132,13329.98,1.09E-06,13.32998,0,0.2439306,9756.156,0.06895,,,,
584.2856,109.9967,153.5405,32.70254,0.09827925,0.2129895,31.6,0.06010752,25.06042,0.06400866,13329.92,1.39E-06,13.32992,0,0.2619591,10453.1,0.06895,,,,
585.5604,109.994,161.6384,31.37338,0.1031952,0.1940961,50,0.3391267,24.99565,0.06384321,13329.87,1.75E-06,13.32987,0,0.2750623,11004.41,0.06895,,,,
586.0297,109.9951,170.6128,27.8541,0.1089465,0.1632592,79.5,1.224654,25.00066,0.063856,13329.93,1.39E-06,13.32993,0,0.2903921,11615.38,0.06895,,,,
597.957,114.9854,70.56835,15.85101,0.04506075,0.2246192,1,0.1226039,24.9999,0.06385407,13348.41,8.03E-07,13.34841,0,0.1201075,4804.32,0.06895,,,,
600.3047,114.9948,75.93476,17.95966,0.04846711,0.2365144,1.6,0.13182,24.98942,0.0638273,13348.75,1.75E-06,13.34876,0,0.129187,5169.668,0.06895,,,,
600.9254,114.9858,81.50747,19.7686,0.05204648,0.2425373,2.5,0.1408724,25.0002,0.06385484,13348.8,1.09E-06,13.3488,0,0.1387276,5549.06,0.06895,,,,
602.3043,114.9982,91.37898,22.09611,0.05836178,0.2418074,5,0.1535774,25.0053,0.06386783,13348.83,9.49E-07,13.34883,0,0.1555608,6221.116,0.06895,,,,
604.4834,114.9958,98.73657,23.2236,0.0630206,0.2352077,7.9,0.157095,24.98931,0.06382702,13348.78,1.24E-06,13.34878,0,0.1679787,6722.024,0.06895,,,,
605.5932,115.003,106.2207,23.9588,0.06782229,0.2255568,12.6,0.1468814,24.99846,0.06385038,13348.75,1.68E-06,13.34874,0,0.1807774,7231.544,0.06895,,,,
606.6801,114.9956,112.9436,24.47239,0.07210944,0.216678,19,0.1111205,24.99656,0.06384555,13348.71,1.97E-06,13.34871,0,0.1922046,7689.242,0.06895,,,,
607.5007,115.0086,121.7123,27.43993,0.0776589,0.2254492,31.6,0.06254925,24.98081,0.06380531,13348.63,2.41E-06,13.34863,0,0.2069965,8286.22,0.06895,,,,
608.6709,114.9951,128.1776,25.97322,0.08190136,0.2026346,50,0.3933784,25.01662,0.06389678,13348.6,2.7E-06,13.3486,0,0.2183046,8726.382,0.06895,,,,
609.1401,114.9996,135.3509,22.10491,0.08642059,0.1633156,79.5,1.283088,24.99803,0.06384928,13348.65,2.26E-06,13.34865,0,0.2303503,9214.741,0,,,,
621.107,119.9808,48.14618,11.6506,0.03074006,0.2419838,1,0.08406101,24.99728,0.06384737,13389.9,2.12E-06,13.38989,0,0.08193632,3277.81,0.06895,,,,
623.4546,119.9996,52.13907,13.27535,0.03326915,0.2546142,1.6,0.09087157,24.98206,0.0638085,13390.49,9.49E-07,13.39049,0,0.08867751,3549.648,0.06895,,,,
624.0753,119.996,56.31489,14.65387,0.03596653,0.260213,2.5,0.09752446,25.00489,0.06386682,13390.51,5.84E-07,13.39051,0,0.09586724,3833.939,0.06895,,,,
625.4729,119.994,63.86196,16.47804,0.04077346,0.2580259,5,0.1062192,24.99684,0.06384624,13390.44,1.09E-06,13.39044,0,0.1086799,4347.747,0.06895,,,,
628.1626,119.9957,69.80097,17.41916,0.04453506,0.2495548,7.9,0.1074422,24.97988,0.06380293,13390.01,8.76E-07,13.39001,0,0.1187063,4752.076,0.06895,,,,
629.1914,119.9948,75.62774,18.03091,0.0482695,0.2384166,12.6,0.09471679,24.98858,0.06382514,13389.81,2.48E-06,13.38981,0,0.1286603,5148.765,0.06895,,,,
630.2863,120.0044,80.91656,18.38855,0.05160508,0.2272533,19,0.05848426,24.9692,0.06377568,13389.59,9.49E-07,13.38959,0,0.1375511,5508.83,0.06895,,,,
631.285,120.0062,87.80359,21.32562,0.05611126,0.2428787,31.6,0.1033478,25.02002,0.06390545,13389.38,2.41E-06,13.38939,0,0.1495622,5977.701,0.06895,,,,
632.4545,119.9964,92.51814,19.74517,0.05908325,0.2134194,50,0.4515469,25.00272,0.06386127,13389.21,3.65E-07,13.38921,0,0.1574839,6298.67,0.06895,,,,
632.9238,119.9936,98.0108,15.92726,0.06258666,0.1625052,79.5,1.345615,25.00101,0.0638569,13389.25,1.46E-07,13.38925,0,0.166822,6672.612,0.06895,,,,
644.8801,124.977,18.72596,5.922609,0.01196019,0.316278,1,0.03339158,25.00597,0.06386957,13566.61,1.17E-06,13.56661,0,0.03187937,1274.87,0.06895,,,,
647.3965,124.997,20.07575,6.387316,0.01283075,0.3181608,1.6,0.03549202,25.02246,0.06391169,13575.7,1.75E-06,13.5757,0,0.03419981,1366.765,0.06895,,,,
648.2961,124.9897,21.99686,6.910712,0.01404933,0.3141682,2.5,0.03800964,25.00603,0.06386972,13576.74,5.84E-07,13.57674,0,0.03744789,1497.554,0.06895,,,,
650.4898,125.0016,25.55125,7.6352,0.01631774,0.298819,5,0.03982144,25.00331,0.0638628,13575.76,1.31E-06,13.57577,0,0.04349424,1739.539,0.06895,,,,
654.0863,125.0009,28.91033,8.172708,0.01841101,0.2826916,7.9,0.03687548,24.93299,0.06368316,13571.67,1.53E-06,13.57167,0,0.04907377,1968.226,0.06895,,,,
655.5806,124.9949,32.01621,8.579972,0.02037785,0.2679883,12.6,0.02198172,24.91944,0.06364856,13570.11,1.31E-06,13.57012,0,0.05431629,2179.676,0.06895,,,,
657.0363,124.9981,34.89683,8.919735,0.02231238,0.255603,19,0.033696,25.03282,0.06393814,13568.32,1.39E-06,13.56832,0,0.0594727,2375.79,0.06895,,,,
658.152,125.0024,38.72866,11.9027,0.02474614,0.3073358,31.6,0.1801366,25.01639,0.06389619,13566.4,2.41E-06,13.56641,0,0.06595976,2636.662,0.06895,,,,
659.3224,124.9934,40.88598,10.6896,0.02611402,0.2614489,50,0.5375373,25.00627,0.06387034,13564.69,2.48E-06,13.56469,0,0.06960579,2783.534,0.06895,,,,
659.8282,124.996,43.82488,6.925319,0.02798351,0.1580226,79.5,1.436682,24.99949,0.06385303,13564.28,1.97E-06,13.56428,0,0.07458884,2983.614,0.06895,,,,
660.0237,124.9951,42.45738,17.21535,0.02710867,0.4054738,100,2.316477,24.99797,0.06384914,13564.06,4.38E-07,13.56407,0,0.07225699,2890.514,0.06895,,,,